Workbook

Sheet Original Data
A1: Site | B1: Transect | C1: Pavona gigantea | D1: Pavona varians | E1: Pocillopora effusa | F1: Porites lobata | G1: Psammocora stellata | H1: Ascidian (colonial) | I1: Ascidian (solitary) | J1: Diadema sp | K1: Soft Coral | L1: Sponge | M1: Gravel | N1: Sand | O1: Dead coral | P1: Rock | Q1: tag/frame/zspar etc | R1: Unknown | S1: Caulerpa spp. | T1: Galaxaura | U1: Jania | V1: Padina | W1: Pink CCA | X1: Red CCA | Y1: Turf algae | Z1: White CCA
A2: Papagayo1 | B2: T1 | C2: 0 | D2: 0 | E2: 0 | F2: 0 | G2: 0 | H2: 0 | I2: 0 | J2: 0 | K2: 0 | L2: 0 | M2: 0 | N2: 0 | O2: 0 | P2: 0 | Q2: 4 | R2: 0 | S2: 0 | T2: 0 | U2: 0 | V2: 0 | W2: 0 | X2: 8 | Y2: 88 | Z2: 0
A3: Papagayo1 | B3: T1 | C3: 0 | D3: 0 | E3: 20 | F3: 0 | G3: 0 | H3: 0 | I3: 0 | J3: 0 | K3: 0 | L3: 0 | M3: 8 | N3: 0 | O3: 0 | P3: 0 | Q3: 4 | R3: 0 | S3: 0 | T3: 0 | U3: 0 | V3: 0 | W3: 16 | X3: 0 | Y3: 52 | Z3: 0
A4: Papagayo1 | B4: T1 | C4: 0 | D4: 0 | E4: 32 | F4: 0 | G4: 0 | H4: 0 | I4: 0 | J4: 0 | K4: 0 | L4: 0 | M4: 0 | N4: 4 | O4: 0 | P4: 0 | Q4: 4 | R4: 0 | S4: 0 | T4: 0 | U4: 0 | V4: 0 | W4: 4 | X4: 8 | Y4: 48 | Z4: 0
A5: Papagayo1 | B5: T1 | C5: 0 | D5: 0 | E5: 12 | F5: 0 | G5: 0 | H5: 0 | I5: 0 | J5: 4 | K5: 0 | L5: 0 | M5: 0 | N5: 0 | O5: 0 | P5: 0 | Q5: 0 | R5: 0 | S5: 0 | T5: 0 | U5: 0 | V5: 0 | W5: 28 | X5: 4 | Y5: 52 | Z5: 0
A6: Papagayo1 | B6: T1 | C6: 0 | D6: 0 | E6: 28 | F6: 0 | G6: 0 | H6: 0 | I6: 0 | J6: 0 | K6: 0 | L6: 0 | M6: 0 | N6: 4 | O6: 0 | P6: 0 | Q6: 0 | R6: 0 | S6: 0 | T6: 0 | U6: 0 | V6: 0 | W6: 20 | X6: 8 | Y6: 40 | Z6: 0
A7: Papagayo1 | B7: T1 | C7: 0 | D7: 0 | E7: 0 | F7: 0 | G7: 0 | H7: 0 | I7: 0 | J7: 0 | K7: 0 | L7: 0 | M7: 4 | N7: 0 | O7: 0 | P7: 0 | Q7: 0 | R7: 0 | S7: 0 | T7: 4 | U7: 0 | V7: 0 | W7: 24 | X7: 4 | Y7: 64 | Z7: 0
A8: Papagayo1 | B8: T1 | C8: 0 | D8: 0 | E8: 16 | F8: 0 | G8: 0 | H8: 0 | I8: 0 | J8: 0 | K8: 0 | L8: 0 | M8: 0 | N8: 0 | O8: 0 | P8: 0 | Q8: 0 | R8: 0 | S8: 0 | T8: 0 | U8: 0 | V8: 0 | W8: 24 | X8: 0 | Y8: 56 | Z8: 4
A9: Papagayo1 | B9: T1 | C9: 0 | D9: 0 | E9: 20 | F9: 0 | G9: 0 | H9: 0 | I9: 0 | J9: 4 | K9: 0 | L9: 0 | M9: 0 | N9: 0 | O9: 0 | P9: 0 | Q9: 0 | R9: 0 | S9: 0 | T9: 0 | U9: 0 | V9: 0 | W9: 48 | X9: 8 | Y9: 16 | Z9: 4
A10: Papagayo1 | B10: T1 | C10: 0 | D10: 0 | E10: 8 | F10: 0 | G10: 0 | H10: 0 | I10: 0 | J10: 4 | K10: 0 | L10: 0 | M10: 4 | N10: 0 | O10: 0 | P10: 0 | Q10: 0 | R10: 0 | S10: 0 | T10: 0 | U10: 0 | V10: 0 | W10: 60 | X10: 4 | Y10: 20 | Z10: 0
A11: Papagayo1 | B11: T1 | C11: 0 | D11: 0 | E11: 0 | F11: 0 | G11: 0 | H11: 0 | I11: 0 | J11: 0 | K11: 0 | L11: 32 | M11: 0 | N11: 0 | O11: 0 | P11: 4 | Q11: 0 | R11: 0 | S11: 0 | T11: 8 | U11: 0 | V11: 0 | W11: 8 | X11: 20 | Y11: 28 | Z11: 0
A12: Papagayo1 | B12: T1 | C12: 0 | D12: 0 | E12: 24 | F12: 0 | G12: 0 | H12: 0 | I12: 0 | J12: 0 | K12: 0 | L12: 0 | M12: 4 | N12: 0 | O12: 0 | P12: 0 | Q12: 0 | R12: 0 | S12: 0 | T12: 0 | U12: 0 | V12: 0 | W12: 12 | X12: 8 | Y12: 48 | Z12: 4
A13: Papagayo1 | B13: T1 | C13: 0 | D13: 0 | E13: 16 | F13: 0 | G13: 0 | H13: 0 | I13: 0 | J13: 4 | K13: 0 | L13: 0 | M13: 0 | N13: 0 | O13: 0 | P13: 0 | Q13: 8 | R13: 0 | S13: 0 | T13: 0 | U13: 0 | V13: 0 | W13: 44 | X13: 8 | Y13: 20 | Z13: 0
... A842: Samara4 | B842: T2 | C842: 0 | D842: 0 | E842: 0 | F842: 0 | G842: 0 | H842: 0 | I842: 0 | J842: 0 | K842: 4 | L842: 0 | M842: 0 | N842: 0 | O842: 0 | P842: 0 | Q842: 0 | R842: 0 | S842: 0 | T842: 4 | U842: 0 | V842: 0 | W842: 4 | X842: 0 | Y842: 80 | Z842: 8

Sheet With Stats
A1: Site | B1: Transect | C1: Statistic | D1: Pavona gigantea | E1: Pavona varians | F1: Pocillopora effusa | G1: Porites lobata | H1: Psammocora stellata | I1: Ascidian (colonial) | J1: Ascidian (solitary) | K1: Diadema sp | L1: Soft Coral | M1: Sponge | N1: Gravel | O1: Sand | P1: Dead coral | Q1: Rock | R1: tag/frame/zspar etc | S1: Unknown | T1: Caulerpa spp. | U1: Galaxaura | V1: Jania | W1: Padina | X1: Pink CCA | Y1: Red CCA | Z1: Turf algae | AA1: White CCA
A2: Papagayo1 | B2: T1 | D2: 0 | E2: 0 | F2: 0 | G2: 0 | H2: 0 | I2: 0 | J2: 0 | K2: 0 | L2: 0 | M2: 0 | N2: 0 | O2: 0 | P2: 0 | Q2: 0 | R2: 4 | S2: 0 | T2: 0 | U2: 0 | V2: 0 | W2: 0 | X2: 0 | Y2: 8 | Z2: 88 | AA2: 0
A3: Papagayo1 | B3: T1 | D3: 0 | E3: 0 | F3: 20 | G3: 0 | H3: 0 | I3: 0 | J3: 0 | K3: 0 | L3: 0 | M3: 0 | N3: 8 | O3: 0 | P3: 0 | Q3: 0 | R3: 4 | S3: 0 | T3: 0 | U3: 0 | V3: 0 | W3: 0 | X3: 16 | Y3: 0 | Z3: 52 | AA3: 0
A4: Papagayo1 | B4: T1 | D4: 0 | E4: 0 | F4: 32 | G4: 0 | H4: 0 | I4: 0 | J4: 0 | K4: 0 | L4: 0 | M4: 0 | N4: 0 | O4: 4 | P4: 0 | Q4: 0 | R4: 4 | S4: 0 | T4: 0 | U4: 0 | V4: 0 | W4: 0 | X4: 4 | Y4: 8 | Z4: 48 | AA4: 0
A5: Papagayo1 | B5: T1 | D5: 0 | E5: 0 | F5: 12 | G5: 0 | H5: 0 | I5: 0 | J5: 0 | K5: 4 | L5: 0 | M5: 0 | N5: 0 | O5: 0 | P5: 0 | Q5: 0 | R5: 0 | S5: 0 | T5: 0 | U5: 0 | V5: 0 | W5: 0 | X5: 28 | Y5: 4 | Z5: 52 | AA5: 0
A6: Papagayo1 | B6: T1 | D6: 0 | E6: 0 | F6: 28 | G6: 0 | H6: 0 | I6: 0 | J6: 0 | K6: 0 | L6: 0 | M6: 0 | N6: 0 | O6: 4 | P6: 0 | Q6: 0 | R6: 0 | S6: 0 | T6: 0 | U6: 0 | V6: 0 | W6: 0 | X6: 20 | Y6: 8 | Z6: 40 | AA6: 0
A7: Papagayo1 | B7: T1 | D7: 0 | E7: 0 | F7: 0 | G7: 0 | H7: 0 | I7: 0 | J7: 0 | K7: 0 | L7: 0 | M7: 0 | N7: 4 | O7: 0 | P7: 0 | Q7: 0 | R7: 0 | S7: 0 | T7: 0 | U7: 4 | V7: 0 | W7: 0 | X7: 24 | Y7: 4 | Z7: 64 | AA7: 0
A8: Papagayo1 | B8: T1 | D8: 0 | E8: 0 | F8: 16 | G8: 0 | H8: 0 | I8: 0 | J8: 0 | K8: 0 | L8: 0 | M8: 0 | N8: 0 | O8: 0 | P8: 0 | Q8: 0 | R8: 0 | S8: 0 | T8: 0 | U8: 0 | V8: 0 | W8: 0 | X8: 24 | Y8: 0 | Z8: 56 | AA8: 4
A9: Papagayo1 | B9: T1 | D9: 0 | E9: 0 | F9: 20 | G9: 0 | H9: 0 | I9: 0 | J9: 0 | K9: 4 | L9: 0 | M9: 0 | N9: 0 | O9: 0 | P9: 0 | Q9: 0 | R9: 0 | S9: 0 | T9: 0 | U9: 0 | V9: 0 | W9: 0 | X9: 48 | Y9: 8 | Z9: 16 | AA9: 4
A10: Papagayo1 | B10: T1 | D10: 0 | E10: 0 | F10: 8 | G10: 0 | H10: 0 | I10: 0 | J10: 0 | K10: 4 | L10: 0 | M10: 0 | N10: 4 | O10: 0 | P10: 0 | Q10: 0 | R10: 0 | S10: 0 | T10: 0 | U10: 0 | V10: 0 | W10: 0 | X10: 60 | Y10: 4 | Z10: 20 | AA10: 0
A11: Papagayo1 | B11: T1 | D11: 0 | E11: 0 | F11: 0 | G11: 0 | H11: 0 | I11: 0 | J11: 0 | K11: 0 | L11: 0 | M11: 32 | N11: 0 | O11: 0 | P11: 0 | Q11: 4 | R11: 0 | S11: 0 | T11: 0 | U11: 8 | V11: 0 | W11: 0 | X11: 8 | Y11: 20 | Z11: 28 | AA11: 0
A12: Papagayo1 | B12: T1 | D12: 0 | E12: 0 | F12: 24 | G12: 0 | H12: 0 | I12: 0 | J12: 0 | K12: 0 | L12: 0 | M12: 0 | N12: 4 | O12: 0 | P12: 0 | Q12: 0 | R12: 0 | S12: 0 | T12: 0 | U12: 0 | V12: 0 | W12: 0 | X12: 12 | Y12: 8 | Z12: 48 | AA12: 4
A13: Papagayo1 | B13: T1 | D13: 0 | E13: 0 | F13: 16 | G13: 0 | H13: 0 | I13: 0 | J13: 0 | K13: 4 | L13: 0 | M13: 0 | N13: 0 | O13: 0 | P13: 0 | Q13: 0 | R13: 8 | S13: 0 | T13: 0 | U13: 0 | V13: 0 | W13: 0 | X13: 44 | Y13: 8 | Z13: 20 | AA13: 0
... A16: Papagayo1 | B16: T1 | D16: 0 | E16: 0 | F16: 0 | G16: 0 | H16: 0 | I16: 0 | J16: 0 | K16: 0 | L16: 0 | M16: 0 | N16: 0 | O16: 0 | P16: 0 | Q16: 0 | R16: 4 | S16: 0 | T16: 0 | U16: 0 | V16: 0 | W16: 0 | X16: 4 | Y16: 8 | Z16: 84 | AA16: 0
A17: Papagayo1 | B17: T1 | C17: Mean | D17: 0 | E17: 0 | F17: 13.066667 | G17: 0 | H17: 0 | I17: 0 | J17: 0 | K17: 1.0666667 | L17: 0 | M17: 2.1333333 | N17: 2.1333333 | O17: 0.8 | P17: 0 | Q17: 0.26666667 | R17: 2.4 | S17: 0 | T17: 0 | U17: 0.8 | V17: 0 | W17: 0 | X17: 23.2 | Y17: 6.1333333 | Z17: 47.2 | AA17: 0.8
A18: Papagayo1 | B18: T1 | C18: SD | D18: 0 | E18: 0 | F18: 10.740223 | G18: 0 | H18: 0 | I18: 0 | J18: 0 | K18: 1.8309508 | L18: 0 | M18: 8.2623645 | N18: 3.6619017 | O18: 1.6561573 | P18: 0 | Q18: 1.0327956 | R18: 2.9471536 | S18: 0 | T18: 0 | U18: 2.2424476 | V18: 0 | W18: 0 | X18: 18.834619 | Y18: 4.9837832 | Z18: 21.867131 | AA18: 1.6561573
A19: Papagayo1 | B19: T1 | C19: Median | D19: 0 | E19: 0 | F19: 16 | G19: 0 | H19: 0 | I19: 0 | J19: 0 | K19: 0 | L19: 0 | M19: 0 | N19: 0 | O19: 0 | P19: 0 | Q19: 0 | R19: 0 | S19: 0 | T19: 0 | U19: 0 | V19: 0 | W19: 0 | X19: 20 | Y19: 8 | Z19: 48 | AA19: 0
A20: Papagayo1 | B20: T1 | C20: Q25 | D20: 0 | E20: 0 | F20: 2 | G20: 0 | H20: 0 | I20: 0 | J20: 0 | K20: 0 | L20: 0 | M20: 0 | N20: 0 | O20: 0 | P20: 0 | Q20: 0 | R20: 0 | S20: 0 | T20: 0 | U20: 0 | V20: 0 | W20: 0 | X20: 8 | Y20: 4 | Z20: 30 | AA20: 0
A21: Papagayo1 | B21: T1 | C21: Q75 | D21: 0 | E21: 0 | F21: 20 | G21: 0 | H21: 0 | I21: 0 | J21: 0 | K21: 2 | L21: 0 | M21: 0 | N21: 4 | O21: 0 | P21: 0 | Q21: 0 | R21: 4 | S21: 0 | T21: 0 | U21: 0 | V21: 0 | W21: 0 | X21: 36 | Y21: 8 | Z21: 58 | AA21: 0
A22: Papagayo1 | B22: T2 | D22: 0 | E22: 0 | F22: 0 | G22: 8 | H22: 0 | I22: 0 | J22: 0 | K22: 0 | L22: 0 | M22: 0 | N22: 0 | O22: 0 | P22: 0 | Q22: 0 | R22: 0 | S22: 0 | T22: 0 | U22: 0 | V22: 0 | W22: 0 | X22: 8 | Y22: 0 | Z22: 84 | AA22: 0
A23: Papagayo1 | B23: T2 | D23: 0 | E23: 0 | F23: 24 | G23: 0 | H23: 0 | I23: 0 | J23: 0 | K23: 0 | L23: 0 | M23: 0 | N23: 0 | O23: 0 | P23: 0 | Q23: 0 | R23: 0 | S23: 0 | T23: 0 | U23: 0 | V23: 0 | W23: 0 | X23: 8 | Y23: 4 | Z23: 60 | AA23: 4
A24: Papagayo1 | B24: T2 | D24: 0 | E24: 0 | F24: 20 | G24: 0 | H24: 0 | I24: 0 | J24: 0 | K24: 4 | L24: 0 | M24: 0 | N24: 0 | O24: 4 | P24: 0 | Q24: 0 | R24: 0 | S24: 0 | T24: 0 | U24: 0 | V24: 0 | W24: 0 | X24: 44 | Y24: 0 | Z24: 16 | AA24: 12
A25: Papagayo1 | B25: T2 | D25: 0 | E25: 0 | F25: 24 | G25: 0 | H25: 0 | I25: 0 | J25: 0 | K25: 4 | L25: 0 | M25: 0 | N25: 12 | O25: 0 | P25: 0 | Q25: 0 | R25: 4 | S25: 0 | T25: 0 | U25: 0 | V25: 0 | W25: 0 | X25: 40 | Y25: 0 | Z25: 8 | AA25: 8
A26: Papagayo1 | B26: T2 | D26: 0 | E26: 0 | F26: 28 | G26: 0 | H26: 0 | I26: 0 | J26: 0 | K26: 8 | L26: 0 | M26: 0 | N26: 0 | O26: 0 | P26: 0 | Q26: 0 | R26: 0 | S26: 0 | T26: 0 | U26: 0 | V26: 0 | W26: 0 | X26: 40 | Y26: 0 | Z26: 24 | AA26: 0
A27: Papagayo1 | B27: T2 | D27: 0 | E27: 0 | F27: 0 | G27: 0 | H27: 0 | I27: 0 | J27: 0 | K27: 0 | L27: 0 | M27: 0 | N27: 0 | O27: 0 | P27: 0 | Q27: 0 | R27: 0 | S27: 0 | T27: 0 | U27: 4 | V27: 4 | W27: 0 | X27: 28 | Y27: 4 | Z27: 60 | AA27: 0
A28: Papagayo1 | B28: T2 | D28: 0 | E28: 0 | F28: 24 | G28: 0 | H28: 0 | I28: 0 | J28: 0 | K28: 0 | L28: 0 | M28: 0 | N28: 0 | O28: 0 | P28: 0 | Q28: 0 | R28: 0 | S28: 0 | T28: 0 | U28: 0 | V28: 0 | W28: 0 | X28: 32 | Y28: 0 | Z28: 40 | AA28: 4
A29: Papagayo1 | B29: T2 | D29: 0 | E29: 0 | F29: 0 | G29: 0 | H29: 0 | I29: 0 | J29: 4 | K29: 0 | L29: 0 | M29: 0 | N29: 0 | O29: 0 | P29: 0 | Q29: 0 | R29: 0 | S29: 0 | T29: 0 | U29: 0 | V29: 4 | W29: 0 | X29: 16 | Y29: 8 | Z29: 68 | AA29: 0
A30: Papagayo1 | B30: T2 | D30: 0 | E30: 0 | F30: 24 | G30: 0 | H30: 0 | I30: 0 | J30: 0 | K30: 0 | L30: 0 | M30: 0 | N30: 0 | O30: 0 | P30: 0 | Q30: 0 | R30: 0 | S30: 0 | T30: 0 | U30: 0 | V30: 0 | W30: 0 | X30: 8 | Y30: 0 | Z30: 64 | AA30: 4
A31: Papagayo1 | B31: T2 | D31: 0 | E31: 0 | F31: 0 | G31: 0 | H31: 0 | I31: 0 | J31: 0 | K31: 0 | L31: 0 | M31: 4 | N31: 0 | O31: 0 | P31: 0 | Q31: 4 | R31: 4 | S31: 0 | T31: 0 | U31: 0 | V31: 0 | W31: 0 | X31: 44 | Y31: 28 | Z31: 16 | AA31: 0
A32: Papagayo1 | B32: T2 | D32: 0 | E32: 0 | F32: 0 | G32: 0 | H32: 0 | I32: 0 | J32: 0 | K32: 0 | L32: 0 | M32: 8 | N32: 0 | O32: 0 | P32: 0 | Q32: 0 | R32: 8 | S32: 0 | T32: 0 | U32: 0 | V32: 0 | W32: 0 | X32: 12 | Y32: 24 | Z32: 48 | AA32: 0
A33: Papagayo1 | B33: T2 | D33: 0 | E33: 0 | F33: 44 | G33: 0 | H33: 0 | I33: 0 | J33: 0 | K33: 8 | L33: 0 | M33: 0 | N33: 0 | O33: 0 | P33: 0 | Q33: 0 | R33: 0 | S33: 0 | T33: 0 | U33: 0 | V33: 0 | W33: 0 | X33: 44 | Y33: 0 | Z33: 0 | AA33: 4
... A36: Papagayo1 | B36: T2 | D36: 0 | E36: 0 | F36: 0 | G36: 0 | H36: 0 | I36: 0 | J36: 0 | K36: 0 | L36: 0 | M36: 0 | N36: 0 | O36: 0 | P36: 0 | Q36: 4 | R36: 0 | S36: 0 | T36: 0 | U36: 0 | V36: 0 | W36: 0 | X36: 72 | Y36: 8 | Z36: 12 | AA36: 4
A37: Papagayo1 | B37: T2 | C37: Mean | D37: 0 | E37: 0 | F37: 14.133333 | G37: 0.53333333 | H37: 0 | I37: 0 | J37: 0.26666667 | K37: 1.6 | L37: 0 | M37: 1.0666667 | N37: 1.0666667 | O37: 0.26666667 | P37: 0 | Q37: 0.53333333 | R37: 1.0666667 | S37: 0 | T37: 0 | U37: 0.26666667 | V37: 0.53333333 | W37: 0 | X37: 31.733333 | Y37: 5.8666667 | Z37: 38.133333 | AA37: 2.9333333
A38: Papagayo1 | B38: T2 | C38: SD | D38: 0 | E38: 0 | F38: 14.647607 | G38: 2.0655911 | H38: 0 | I38: 0 | J38: 1.0327956 | K38: 2.9471536 | L38: 0 | M38: 2.3744674 | N38: 3.1952345 | O38: 1.0327956 | P38: 0 | Q38: 1.4074631 | R38: 2.3744674 | S38: 0 | T38: 0 | U38: 1.0327956 | V38: 1.4074631 | W38: 0 | X38: 21.933232 | Y38: 8.7982682 | Z38: 26.005128 | AA38: 3.5348604
A39: Papagayo1 | B39: T2 | C39: Median | D39: 0 | E39: 0 | F39: 20 | G39: 0 | H39: 0 | I39: 0 | J39: 0 | K39: 0 | L39: 0 | M39: 0 | N39: 0 | O39: 0 | P39: 0 | Q39: 0 | R39: 0 | S39: 0 | T39: 0 | U39: 0 | V39: 0 | W39: 0 | X39: 32 | Y39: 4 | Z39: 40 | AA39: 4
A40: Papagayo1 | B40: T2 | C40: Q25 | D40: 0 | E40: 0 | F40: 0 | G40: 0 | H40: 0 | I40: 0 | J40: 0 | K40: 0 | L40: 0 | M40: 0 | N40: 0 | O40: 0 | P40: 0 | Q40: 0 | R40: 0 | S40: 0 | T40: 0 | U40: 0 | V40: 0 | W40: 0 | X40: 10 | Y40: 0 | Z40: 16 | AA40: 0
A41: Papagayo1 | B41: T2 | C41: Q75 | D41: 0 | E41: 0 | F41: 24 | G41: 0 | H41: 0 | I41: 0 | J41: 0 | K41: 2 | L41: 0 | M41: 0 | N41: 0 | O41: 0 | P41: 0 | Q41: 0 | R41: 0 | S41: 0 | T41: 0 | U41: 0 | V41: 0 | W41: 0 | X41: 44 | Y41: 8 | Z41: 60 | AA41: 4
A42: Papagayo1 | B42: T3 | D42: 0 | E42: 0 | F42: 32 | G42: 0 | H42: 0 | I42: 0 | J42: 0 | K42: 0 | L42: 0 | M42: 4 | N42: 0 | O42: 0 | P42: 0 | Q42: 0 | R42: 4 | S42: 0 | T42: 0 | U42: 0 | V42: 0 | W42: 0 | X42: 8 | Y42: 4 | Z42: 40 | AA42: 8
A43: Papagayo1 | B43: T3 | D43: 0 | E43: 0 | F43: 20 | G43: 0 | H43: 0 | I43: 0 | J43: 0 | K43: 0 | L43: 0 | M43: 0 | N43: 0 | O43: 0 | P43: 0 | Q43: 0 | R43: 0 | S43: 0 | T43: 0 | U43: 0 | V43: 0 | W43: 0 | X43: 28 | Y43: 8 | Z43: 44 | AA43: 0
A44: Papagayo1 | B44: T3 | D44: 0 | E44: 0 | F44: 20 | G44: 0 | H44: 0 | I44: 0 | J44: 0 | K44: 0 | L44: 0 | M44: 0 | N44: 0 | O44: 0 | P44: 0 | Q44: 0 | R44: 4 | S44: 0 | T44: 0 | U44: 0 | V44: 0 | W44: 0 | X44: 16 | Y44: 8 | Z44: 52 | AA44: 0
...

Sheet Photos_Averages
A1: Site | B1: Transect | C1: Pavona gigantea | D1: Pavona varians | E1: Pocillopora effusa | F1: Porites lobata | G1: Psammocora stellata | H1: Ascidian (colonial) | I1: Ascidian (solitary) | J1: Diadema sp | K1: Soft Coral | L1: Sponge | M1: Gravel | N1: Sand | O1: Dead coral | P1: Rock | Q1: tag/frame/zspar etc | R1: Unknown | S1: Caulerpa spp. | T1: Galaxaura | U1: Jania | V1: Padina | W1: Pink CCA | X1: Red CCA | Y1: Turf algae | Z1: White CCA
A2: Papagayo1 | B2: T1 | C2: 0 | D2: 0 | E2: 13.066667 | F2: 0 | G2: 0 | H2: 0 | I2: 0 | J2: 1.0666667 | K2: 0 | L2: 2.1333333 | M2: 2.1333333 | N2: 0.8 | O2: 0 | P2: 0.26666667 | Q2: 2.4 | R2: 0 | S2: 0 | T2: 0.8 | U2: 0 | V2: 0 | W2: 23.2 | X2: 6.1333333 | Y2: 47.2 | Z2: 0.8
A3: Papagayo1 | B3: T2 | C3: 0 | D3: 0 | E3: 14.133333 | F3: 0.53333333 | G3: 0 | H3: 0 | I3: 0.26666667 | J3: 1.6 | K3: 0 | L3: 1.0666667 | M3: 1.0666667 | N3: 0.26666667 | O3: 0 | P3: 0.53333333 | Q3: 1.0666667 | R3: 0 | S3: 0 | T3: 0.26666667 | U3: 0.53333333 | V3: 0 | W3: 31.733333 | X3: 5.8666667 | Y3: 38.133333 | Z3: 2.9333333
A4: Papagayo1 | B4: T3 | C4: 0 | D4: 0 | E4: 16 | F4: 0 | G4: 0 | H4: 0 | I4: 0.26666667 | J4: 0.8 | K4: 0 | L4: 0.26666667 | M4: 0.8 | N4: 0.26666667 | O4: 0 | P4: 0 | Q4: 2.9333333 | R4: 0 | S4: 0 | T4: 0 | U4: 0 | V4: 0 | W4: 29.333333 | X4: 4.5333333 | Y4: 41.866667 | Z4: 2.9333333
A5: Papagayo1 | B5: T4 | C5: 0 | D5: 0 | E5: 12.8 | F5: 0 | G5: 0 | H5: 0 | I5: 0.26666667 | J5: 1.6 | K5: 1.0666667 | L5: 0.53333333 | M5: 0.26666667 | N5: 0.26666667 | O5: 0 | P5: 0 | Q5: 1.3333333 | R5: 0 | S5: 0 | T5: 0 | U5: 0 | V5: 0 | W5: 36 | X5: 4.8 | Y5: 37.333333 | Z5: 3.7333333
A6: Papagayo1 | B6: T5 | C6: 0 | D6: 0 | E6: 4.8 | F6: 0.26666667 | G6: 0 | H6: 0 | I6: 0 | J6: 4.8 | K6: 0 | L6: 0 | M6: 0 | N6: 0 | O6: 0 | P6: 0 | Q6: 1.6 | R6: 0 | S6: 0 | T6: 0 | U6: 0 | V6: 0 | W6: 53.6 | X6: 2.4 | Y6: 19.466667 | Z6: 13.066667
A7: Papagayo1 | B7: T6 | C7: 0 | D7: 0 | E7: 3.7333333 | F7: 0 | G7: 0 | H7: 0 | I7: 0 | J7: 6.1333333 | K7: 0.26666667 | L7: 0 | M7: 0 | N7: 0 | O7: 0 | P7: 0 | Q7: 0.8 | R7: 0 | S7: 0 | T7: 0 | U7: 0 | V7: 0 | W7: 45.866667 | X7: 1.8666667 | Y7: 31.466667 | Z7: 9.8666667
A8: Papagayo2 | B8: T1 | C8: 2.4 | D8: 0 | E8: 4.8 | F8: 1.6 | G8: 0.26666667 | H8: 0 | I8: 0 | J8: 1.8666667 | K8: 0 | L8: 0 | M8: 0.8 | N8: 2.4 | O8: 0 | P8: 0 | Q8: 0.26666667 | R8: 0.53333333 | S8: 0 | T8: 0 | U8: 0 | V8: 0 | W8: 28.533333 | X8: 1.0666667 | Y8: 54.4 | Z8: 1.0666667
A9: Papagayo2 | B9: T2 | C9: 2.6666667 | D9: 0 | E9: 7.2 | F9: 0 | G9: 0 | H9: 0 | I9: 0 | J9: 1.0666667 | K9: 0 | L9: 0 | M9: 2.6666667 | N9: 3.7333333 | O9: 0 | P9: 1.3333333 | Q9: 1.8666667 | R9: 0 | S9: 0 | T9: 0 | U9: 0 | V9: 0 | W9: 12 | X9: 0.53333333 | Y9: 65.866667 | Z9: 1.0666667
A10: Papagayo2 | B10: T3 | C10: 4 | D10: 0 | E10: 4 | F10: 0.26666667 | G10: 0.53333333 | H10: 0 | I10: 0 | J10: 0.8 | K10: 0 | L10: 0 | M10: 1.0666667 | N10: 5.0666667 | O10: 0 | P10: 0 | Q10: 1.6 | R10: 0 | S10: 0.53333333 | T10: 0 | U10: 0 | V10: 0 | W10: 20 | X10: 2.6666667 | Y10: 58.666667 | Z10: 0.8
A11: Papagayo2 | B11: T4 | C11: 6.6666667 | D11: 0 | E11: 2.6666667 | F11: 8.8 | G11: 1.6 | H11: 0 | I11: 0.26666667 | J11: 2.4 | K11: 0 | L11: 0 | M11: 0.26666667 | N11: 0.53333333 | O11: 0 | P11: 0 | Q11: 2.4 | R11: 0 | S11: 0 | T11: 0.53333333 | U11: 0 | V11: 0 | W11: 29.066667 | X11: 1.3333333 | Y11: 41.6 | Z11: 1.8666667
A12: Papagayo2 | B12: T5 | C12: 9.6 | D12: 5.0666667 | E12: 8.2666667 | F12: 4.8 | G12: 0 | H12: 0 | I12: 0 | J12: 2.4 | K12: 0.26666667 | L12: 0 | M12: 0 | N12: 0.26666667 | O12: 0 | P12: 0 | Q12: 1.3333333 | R12: 0 | S12: 0 | T12: 0 | U12: 0 | V12: 0 | W12: 20.8 | X12: 0.53333333 | Y12: 46.133333 | Z12: 0.53333333
A13: Papagayo2 | B13: T6 | C13: 2.4 | D13: 8 | E13: 2.9333333 | F13: 0 | G13: 0 | H13: 0 | I13: 0 | J13: 0.53333333 | K13: 0 | L13: 0 | M13: 8.8 | N13: 5.3333333 | O13: 0 | P13: 0 | Q13: 1.6 | R13: 0 | S13: 0 | T13: 0 | U13: 0 | V13: 0 | W13: 12.8 | X13: 0 | Y13: 57.066667 | Z13: 0.53333333
... A57: Samara4 | B57: T2 | C57: 0 | D57: 0 | E57: 0 | F57: 1 | G57: 0 | H57: 0.5 | I57: 0.25 | J57: 0 | K57: 10.5 | L57: 0 | M57: 0 | N57: 1.5 | O57: 0 | P57: 0 | Q57: 2 | R57: 0 | S57: 0 | T57: 2 | U57: 0 | V57: 0 | W57: 5 | X57: 3 | Y57: 71 | Z57: 3.25

Sheet Site_Averages_combined
A1: Site | B1: Transect | C1: Pavona spp. | D1: Pocillopora effusa | E1: Porites lobata | F1: Psammocora stellata | G1: Filter feeders | H1: Diadema sp | I1: Soft Coral | J1: Substrate | K1: Sea grass | L1: CCA | M1: Turf algae
A2: Papagayo1 | B2: T1 | C2: =SUM(Photos_Averages!C2:D2) -> 0 | D2: 13.066667 | E2: 0 | F2: 0 | G2: =SUM(Photos_Averages!H2,Photos_Averages!I2,Photos_Averages!L2,Photos_Averages!R2) -> 2.1333333 | H2: 1.0666667 | I2: 0 | J2: =SUM(Photos_Averages!M2,Photos_Averages!N2,Photos_Averages!O2,Photos_Averages!P2) -> 3.2 | K2: 0 | L2: =SUM(Photos_Averages!W2,Photos_Averages!X2,Photos_Averages!Z2) -> 30.133333 | M2: =SUM(Photos_Averages!V2,Photos_Averages!U2,Photos_Averages!T2,Photos_Averages!Q2,Photos_Averages!Y2) -> 50.4
A3: Papagayo1 | B3: T2 | C3: =SUM(Photos_Averages!C3:D3) -> 0 | D3: 14.133333 | E3: 0.53333333 | F3: 0 | G3: =SUM(Photos_Averages!H3,Photos_Averages!I3,Photos_Averages!L3,Photos_Averages!R3) -> 1.3333333 | H3: 1.6 | I3: 0 | J3: =SUM(Photos_Averages!M3,Photos_Averages!N3,Photos_Averages!O3,Photos_Averages!P3) -> 1.8666667 | K3: 0 | L3: =SUM(Photos_Averages!W3,Photos_Averages!X3,Photos_Averages!Z3) -> 40.533333 | M3: =SUM(Photos_Averages!V3,Photos_Averages!U3,Photos_Averages!T3,Photos_Averages!Q3,Photos_Averages!Y3) -> 40
A4: Papagayo1 | B4: T3 | C4: =SUM(Photos_Averages!C4:D4) -> 0 | D4: 16 | E4: 0 | F4: 0 | G4: =SUM(Photos_Averages!H4,Photos_Averages!I4,Photos_Averages!L4,Photos_Averages!R4) -> 0.53333333 | H4: 0.8 | I4: 0 | J4: =SUM(Photos_Averages!M4,Photos_Averages!N4,Photos_Averages!O4,Photos_Averages!P4) -> 1.0666667 | K4: 0 | L4: =SUM(Photos_Averages!W4,Photos_Averages!X4,Photos_Averages!Z4) -> 36.8 | M4: =SUM(Photos_Averages!V4,Photos_Averages!U4,Photos_Averages!T4,Photos_Averages!Q4,Photos_Averages!Y4) -> 44.8
A5: Papagayo1 | B5: T4 | C5: =SUM(Photos_Averages!C5:D5) -> 0 | D5: 12.8 | E5: 0 | F5: 0 | G5: =SUM(Photos_Averages!H5,Photos_Averages!I5,Photos_Averages!L5,Photos_Averages!R5) -> 0.8 | H5: 1.6 | I5: 1.0666667 | J5: =SUM(Photos_Averages!M5,Photos_Averages!N5,Photos_Averages!O5,Photos_Averages!P5) -> 0.53333333 | K5: 0 | L5: =SUM(Photos_Averages!W5,Photos_Averages!X5,Photos_Averages!Z5) -> 44.533333 | M5: =SUM(Photos_Averages!V5,Photos_Averages!U5,Photos_Averages!T5,Photos_Averages!Q5,Photos_Averages!Y5) -> 38.666667
A6: Papagayo1 | B6: T5 | C6: =SUM(Photos_Averages!C6:D6) -> 0 | D6: 4.8 | E6: 0.26666667 | F6: 0 | G6: =SUM(Photos_Averages!H6,Photos_Averages!I6,Photos_Averages!L6,Photos_Averages!R6) -> 0 | H6: 4.8 | I6: 0 | J6: =SUM(Photos_Averages!M6,Photos_Averages!N6,Photos_Averages!O6,Photos_Averages!P6) -> 0 | K6: 0 | L6: =SUM(Photos_Averages!W6,Photos_Averages!X6,Photos_Averages!Z6) -> 69.066667 | M6: =SUM(Photos_Averages!V6,Photos_Averages!U6,Photos_Averages!T6,Photos_Averages!Q6,Photos_Averages!Y6) -> 21.066667
A7: Papagayo1 | B7: T6 | C7: =SUM(Photos_Averages!C7:D7) -> 0 | D7: 3.7333333 | E7: 0 | F7: 0 | G7: =SUM(Photos_Averages!H7,Photos_Averages!I7,Photos_Averages!L7,Photos_Averages!R7) -> 0 | H7: 6.1333333 | I7: 0.26666667 | J7: =SUM(Photos_Averages!M7,Photos_Averages!N7,Photos_Averages!O7,Photos_Averages!P7) -> 0 | K7: 0 | L7: =SUM(Photos_Averages!W7,Photos_Averages!X7,Photos_Averages!Z7) -> 57.6 | M7: =SUM(Photos_Averages!V7,Photos_Averages!U7,Photos_Averages!T7,Photos_Averages!Q7,Photos_Averages!Y7) -> 32.266667
A8: Papagayo2 | B8: T1 | C8: =SUM(Photos_Averages!C8:D8) -> 2.4 | D8: 4.8 | E8: 1.6 | F8: 0.26666667 | G8: =SUM(Photos_Averages!H8,Photos_Averages!I8,Photos_Averages!L8,Photos_Averages!R8) -> 0.53333333 | H8: 1.8666667 | I8: 0 | J8: =SUM(Photos_Averages!M8,Photos_Averages!N8,Photos_Averages!O8,Photos_Averages!P8) -> 3.2 | K8: 0 | L8: =SUM(Photos_Averages!W8,Photos_Averages!X8,Photos_Averages!Z8) -> 30.666667 | M8: =SUM(Photos_Averages!V8,Photos_Averages!U8,Photos_Averages!T8,Photos_Averages!Q8,Photos_Averages!Y8) -> 54.666667
A9: Papagayo2 | B9: T2 | C9: =SUM(Photos_Averages!C9:D9) -> 2.6666667 | D9: 7.2 | E9: 0 | F9: 0 | G9: =SUM(Photos_Averages!H9,Photos_Averages!I9,Photos_Averages!L9,Photos_Averages!R9) -> 0 | H9: 1.0666667 | I9: 0 | J9: =SUM(Photos_Averages!M9,Photos_Averages!N9,Photos_Averages!O9,Photos_Averages!P9) -> 7.7333333 | K9: 0 | L9: =SUM(Photos_Averages!W9,Photos_Averages!X9,Photos_Averages!Z9) -> 13.6 | M9: =SUM(Photos_Averages!V9,Photos_Averages!U9,Photos_Averages!T9,Photos_Averages!Q9,Photos_Averages!Y9) -> 67.733333
A10: Papagayo2 | B10: T3 | C10: =SUM(Photos_Averages!C10:D10) -> 4 | D10: 4 | E10: 0.26666667 | F10: 0.53333333 | G10: =SUM(Photos_Averages!H10,Photos_Averages!I10,Photos_Averages!L10,Photos_Averages!R10) -> 0 | H10: 0.8 | I10: 0 | J10: =SUM(Photos_Averages!M10,Photos_Averages!N10,Photos_Averages!O10,Photos_Averages!P10) -> 6.1333333 | K10: 0.53333333 | L10: =SUM(Photos_Averages!W10,Photos_Averages!X10,Photos_Averages!Z10) -> 23.466667 | M10: =SUM(Photos_Averages!V10,Photos_Averages!U10,Photos_Averages!T10,Photos_Averages!Q10,Photos_Averages!Y10) -> 60.266667
A11: Papagayo2 | B11: T4 | C11: =SUM(Photos_Averages!C11:D11) -> 6.6666667 | D11: 2.6666667 | E11: 8.8 | F11: 1.6 | G11: =SUM(Photos_Averages!H11,Photos_Averages!I11,Photos_Averages!L11,Photos_Averages!R11) -> 0.26666667 | H11: 2.4 | I11: 0 | J11: =SUM(Photos_Averages!M11,Photos_Averages!N11,Photos_Averages!O11,Photos_Averages!P11) -> 0.8 | K11: 0 | L11: =SUM(Photos_Averages!W11,Photos_Averages!X11,Photos_Averages!Z11) -> 32.266667 | M11: =SUM(Photos_Averages!V11,Photos_Averages!U11,Photos_Averages!T11,Photos_Averages!Q11,Photos_Averages!Y11) -> 44.533333
A12: Papagayo2 | B12: T5 | C12: =SUM(Photos_Averages!C12:D12) -> 14.666667 | D12: 8.2666667 | E12: 4.8 | F12: 0 | G12: =SUM(Photos_Averages!H12,Photos_Averages!I12,Photos_Averages!L12,Photos_Averages!R12) -> 0 | H12: 2.4 | I12: 0.26666667 | J12: =SUM(Photos_Averages!M12,Photos_Averages!N12,Photos_Averages!O12,Photos_Averages!P12) -> 0.26666667 | K12: 0 | L12: =SUM(Photos_Averages!W12,Photos_Averages!X12,Photos_Averages!Z12) -> 21.866667 | M12: =SUM(Photos_Averages!V12,Photos_Averages!U12,Photos_Averages!T12,Photos_Averages!Q12,Photos_Averages!Y12) -> 47.466667
A13: Papagayo2 | B13: T6 | C13: =SUM(Photos_Averages!C13:D13) -> 10.4 | D13: 2.9333333 | E13: 0 | F13: 0 | G13: =SUM(Photos_Averages!H13,Photos_Averages!I13,Photos_Averages!L13,Photos_Averages!R13) -> 0 | H13: 0.53333333 | I13: 0 | J13: =SUM(Photos_Averages!M13,Photos_Averages!N13,Photos_Averages!O13,Photos_Averages!P13) -> 14.133333 | K13: 0 | L13: =SUM(Photos_Averages!W13,Photos_Averages!X13,Photos_Averages!Z13) -> 13.333333 | M13: =SUM(Photos_Averages!V13,Photos_Averages!U13,Photos_Averages!T13,Photos_Averages!Q13,Photos_Averages!Y13) -> 58.666667
... A57: Samara4 | B57: T2 | C57: =SUM(Photos_Averages!C57:D57) -> 0 | D57: 0 | E57: 1 | F57: 0 | G57: =SUM(Photos_Averages!H57,Photos_Averages!I57,Photos_Averages!L57,Photos_Averages!R57) -> 0.75 | H57: 0 | I57: 10.5 | J57: =SUM(Photos_Averages!M57,Photos_Averages!N57,Photos_Averages!O57,Photos_Averages!P57) -> 1.5 | K57: 0 | L57: =SUM(Photos_Averages!W57,Photos_Averages!X57,Photos_Averages!Z57) -> 11.25 | M57: =SUM(Photos_Averages!V57,Photos_Averages!U57,Photos_Averages!T57,Photos_Averages!Q57,Photos_Averages!Y57) -> 75

Sheet Transect_Averages
A1: Site | B1: Pavona gigantea | C1: Pavona varians | D1: Pocillopora effusa | E1: Porites lobata | F1: Psammocora stellata | G1: Ascidian (colonial) | H1: Ascidian (solitary) | I1: Diadema sp | J1: Soft Coral | K1: Sponge | L1: Gravel | M1: Sand | N1: Dead coral | O1: Rock | P1: tag/frame/zspar etc | Q1: Unknown | R1: Caulerpa spp. | S1: Galaxaura | T1: Jania | U1: Padina | V1: Pink CCA | W1: Red CCA | X1: Turf algae | Y1: White CCA
A2: Papagayo1 | B2: 0 | C2: 0 | D2: 10.755556 | E2: 0.13333333 | F2: 0 | G2: 0 | H2: 0.13333333 | I2: 2.6666667 | J2: 0.22222222 | K2: 0.66666667 | L2: 0.71111111 | M2: 0.26666667 | N2: 0 | O2: 0.13333333 | P2: 1.6888889 | Q2: 0 | R2: 0 | S2: 0.17777778 | T2: 0.088888889 | U2: 0 | V2: 36.622222 | W2: 4.2666667 | X2: 35.911111 | Y2: 5.5555556
A3: Papagayo2 | B3: 4.6222222 | C3: 2.1777778 | D3: 4.9777778 | E3: 2.5777778 | F3: 0.4 | G3: 0 | H3: 0.044444444 | I3: 1.5111111 | J3: 0.044444444 | K3: 0 | L3: 2.2666667 | M3: 2.8888889 | N3: 0 | O3: 0.22222222 | P3: 1.5111111 | Q3: 0.088888889 | R3: 0.088888889 | S3: 0.088888889 | T3: 0 | U3: 0 | V3: 20.533333 | W3: 1.0222222 | X3: 53.955556 | Y3: 0.97777778
A4: Papagayo3 | B4: 1.8666667 | C4: 0 | D4: 12.311111 | E4: 1.2444444 | F4: 0.17777778 | G4: 0 | H4: 0 | I4: 3.7777778 | J4: 0 | K4: 0.13333333 | L4: 1.0222222 | M4: 0.66666667 | N4: 0 | O4: 0.31111111 | P4: 1.2 | Q4: 0.088888889 | R4: 2.3555556 | S4: 0.35555556 | T4: 0 | U4: 0 | V4: 22.088889 | W4: 3.1111111 | X4: 47.022222 | Y4: 2.2666667
A5: Papagayo4 | B5: 0.31111111 | C5: 0 | D5: 16.711111 | E5: 2.4888889 | F5: 0.17777778 | G5: 0 | H5: 0.044444444 | I5: 2.8888889 | J5: 0 | K5: 0 | L5: 0.17777778 | M5: 0.62222222 | N5: 0 | O5: 0.044444444 | P5: 2.0444444 | Q5: 0 | R5: 0.13333333 | S5: 0 | T5: 0 | U5: 2.3555556 | V5: 12.533333 | W5: 1.2888889 | X5: 56.177778 | Y5: 2
A6: Papagayo5 | B6: 2.6666667 | C6: 0 | D6: 5.8222222 | E6: 0.44444444 | F6: 0 | G6: 0 | H6: 0.13333333 | I6: 0.75555556 | J6: 0.13333333 | K6: 0 | L6: 0.53333333 | M6: 0.62222222 | N6: 0 | O6: 0 | P6: 2 | Q6: 0 | R6: 0.044444444 | S6: 0.31111111 | T6: 0 | U6: 0 | V6: 19.822222 | W6: 3.4222222 | X6: 61.866667 | Y6: 1.4222222
A7: Papagayo6 | B7: 0.8 | C7: 0 | D7: 13.511111 | E7: 0.48888889 | F7: 0 | G7: 0.088888889 | H7: 0.13333333 | I7: 0.84444444 | J7: 0.088888889 | K7: 0 | L7: 1.2 | M7: 0.88888889 | N7: 0 | O7: 0 | P7: 0.66666667 | Q7: 0 | R7: 2.6666667 | S7: 0.22222222 | T7: 0 | U7: 0 | V7: 10.133333 | W7: 3.3777778 | X7: 60.177778 | Y7: 4.7111111
A8: Samara1 | B8: 0 | C8: 0 | D8: 0.66666667 | E8: 0.088888889 | F8: 0.66666667 | G8: 0 | H8: 0 | I8: 0.044444444 | J8: 0.088888889 | K8: 0 | L8: 1.5555556 | M8: 0.31111111 | N8: 0.044444444 | O8: 0.8 | P8: 2.0888889 | Q8: 0 | R8: 5.2888889 | S8: 2.1777778 | T8: 0 | U8: 0 | V8: 2.6222222 | W8: 1.2888889 | X8: 74 | Y8: 8.2666667
A9: Samara2 | B9: 0 | C9: 0 | D9: 0.13333333 | E9: 20.4 | F9: 0 | G9: 0 | H9: 0 | I9: 0.17777778 | J9: 0 | K9: 0.044444444 | L9: 1.2 | M9: 6.8 | N9: 0 | O9: 0.57777778 | P9: 1.0666667 | Q9: 0 | R9: 0 | S9: 0.26666667 | T9: 0 | U9: 0 | V9: 2.0888889 | W9: 0.26666667 | X9: 63.422222 | Y9: 3.5555556
A10: Samara3 | B10: 0.22222222 | C10: 0 | D10: 2.9777778 | E10: 2.2666667 | F10: 2.3111111 | G10: 0 | H10: 0 | I10: 0.044444444 | J10: 0.088888889 | K10: 0 | L10: 0.71111111 | M10: 0.66666667 | N10: 0 | O10: 0.088888889 | P10: 1.2 | Q10: 0 | R10: 2.7555556 | S10: 16.622222 | T10: 0 | U10: 0 | V10: 1.5111111 | W10: 0.48888889 | X10: 64.755556 | Y10: 3.2888889
A11: Samara4 | B11: 0 | C11: 0 | D11: 0 | E11: 1.5666667 | F11: 0 | G11: 0.25 | H11: 0.25833333 | I11: 0 | J11: 5.3833333 | K11: 0.26666667 | L11: 0.26666667 | M11: 1.8166667 | N11: 0 | O11: 0.13333333 | P11: 2.4666667 | Q11: 0 | R11: 0 | S11: 1.1333333 | T11: 0 | U11: 0 | V11: 7.4333333 | W11: 3.9 | X11: 72.566667 | Y11: 2.5583333

Sheet Site_Averages_corals_X
A1: Site | B1: Pavona gigantea | C1: Pavona varians | D1: Pocillopora effusa | E1: Porites lobata | F1: Psammocora stellata | G1: Ascidian (colonial) | H1: Ascidian (solitary) | I1: Diadema sp | J1: Soft Coral | K1: Sponge | L1: Gravel | M1: Sand | N1: Dead coral | O1: Rock | P1: Unknown Turf | Q1: Unknown | R1: Caulerpa spp. | S1: Galaxaura | T1: Jania | U1: Padina | V1: Pink CCA | W1: Red CCA | X1: Turf algae | Y1: White CCA
A2: Papagayo1 | B2: 0 | C2: 0 | D2: 10.755556 | E2: 0.13333333 | F2: 0 | G2: 0 | H2: 0.13333333 | I2: 2.6666667 | J2: 0.22222222 | K2: 0.66666667 | L2: 0.71111111 | M2: 0.26666667 | N2: 0 | O2: 0.13333333 | P2: 1.6888889 | Q2: 0 | R2: 0 | S2: 0.17777778 | T2: 0.088888889 | U2: 0 | V2: 36.622222 | W2: 4.2666667 | X2: 35.911111 | Y2: 5.5555556
A3: Papagayo2 | B3: 4.6222222 | C3: 2.1777778 | D3: 4.9777778 | E3: 2.5777778 | F3: 0.4 | G3: 0 | H3: 0.044444444 | I3: 1.5111111 | J3: 0.044444444 | K3: 0 | L3: 2.2666667 | M3: 2.8888889 | N3: 0 | O3: 0.22222222 | P3: 1.5111111 | Q3: 0.088888889 | R3: 0.088888889 | S3: 0.088888889 | T3: 0 | U3: 0 | V3: 20.533333 | W3: 1.0222222 | X3: 53.955556 | Y3: 0.97777778
A4: Papagayo3 | B4: 1.8666667 | C4: 0 | D4: 12.311111 | E4: 1.2444444 | F4: 0.17777778 | G4: 0 | H4: 0 | I4: 3.7777778 | J4: 0 | K4: 0.13333333 | L4: 1.0222222 | M4: 0.66666667 | N4: 0 | O4: 0.31111111 | P4: 1.2 | Q4: 0.088888889 | R4: 2.3555556 | S4: 0.35555556 | T4: 0 | U4: 0 | V4: 22.088889 | W4: 3.1111111 | X4: 47.022222 | Y4: 2.2666667
A5: Papagayo4 | B5: 0.31111111 | C5: 0 | D5: 16.711111 | E5: 2.4888889 | F5: 0.17777778 | G5: 0 | H5: 0.044444444 | I5: 2.8888889 | J5: 0 | K5: 0 | L5: 0.17777778 | M5: 0.62222222 | N5: 0 | O5: 0.044444444 | P5: 2.0444444 | Q5: 0 | R5: 0.13333333 | S5: 0 | T5: 0 | U5: 2.3555556 | V5: 12.533333 | W5: 1.2888889 | X5: 56.177778 | Y5: 2
A6: Papagayo5 | B6: 2.6666667 | C6: 0 | D6: 5.8222222 | E6: 0.44444444 | F6: 0 | G6: 0 | H6: 0.13333333 | I6: 0.75555556 | J6: 0.13333333 | K6: 0 | L6: 0.53333333 | M6: 0.62222222 | N6: 0 | O6: 0 | P6: 2 | Q6: 0 | R6: 0.044444444 | S6: 0.31111111 | T6: 0 | U6: 0 | V6: 19.822222 | W6: 3.4222222 | X6: 61.866667 | Y6: 1.4222222
A7: Papagayo6 | B7: 0.8 | C7: 0 | D7: 13.511111 | E7: 0.48888889 | F7: 0 | G7: 0.088888889 | H7: 0.13333333 | I7: 0.84444444 | J7: 0.088888889 | K7: 0 | L7: 1.2 | M7: 0.88888889 | N7: 0 | O7: 0 | P7: 0.66666667 | Q7: 0 | R7: 2.6666667 | S7: 0.22222222 | T7: 0 | U7: 0 | V7: 10.133333 | W7: 3.3777778 | X7: 60.177778 | Y7: 4.7111111
A8: Samara1 | B8: 0 | C8: 0 | D8: 0.66666667 | E8: 0.088888889 | F8: 0.66666667 | G8: 0 | H8: 0 | I8: 0.044444444 | J8: 0.088888889 | K8: 0 | L8: 1.5555556 | M8: 0.31111111 | N8: 0.044444444 | O8: 0.8 | P8: 2.0888889 | Q8: 0 | R8: 5.2888889 | S8: 2.1777778 | T8: 0 | U8: 0 | V8: 2.6222222 | W8: 1.2888889 | X8: 74 | Y8: 8.2666667
A9: Samara2 | B9: 0 | C9: 0 | D9: 0.13333333 | E9: 20.4 | F9: 0 | G9: 0 | H9: 0 | I9: 0.17777778 | J9: 0 | K9: 0.044444444 | L9: 1.2 | M9: 6.8 | N9: 0 | O9: 0.57777778 | P9: 1.0666667 | Q9: 0 | R9: 0 | S9: 0.26666667 | T9: 0 | U9: 0 | V9: 2.0888889 | W9: 0.26666667 | X9: 63.422222 | Y9: 3.5555556
A10: Samara3 | B10: 0.22222222 | C10: 0 | D10: 2.9777778 | E10: 2.2666667 | F10: 2.3111111 | G10: 0 | H10: 0 | I10: 0.044444444 | J10: 0.088888889 | K10: 0 | L10: 0.71111111 | M10: 0.66666667 | N10: 0 | O10: 0.088888889 | P10: 1.2 | Q10: 0 | R10: 2.7555556 | S10: 16.622222 | T10: 0 | U10: 0 | V10: 1.5111111 | W10: 0.48888889 | X10: 64.755556 | Y10: 3.2888889
A11: Samara4 | B11: 0 | C11: 0 | D11: 0 | E11: 1.5666667 | F11: 0 | G11: 0.25 | H11: 0.25833333 | I11: 0 | J11: 5.3833333 | K11: 0.26666667 | L11: 0.26666667 | M11: 1.8166667 | N11: 0 | O11: 0.13333333 | P11: 2.4666667 | Q11: 0 | R11: 0 | S11: 1.1333333 | T11: 0 | U11: 0 | V11: 7.4333333 | W11: 3.9 | X11: 72.566667 | Y11: 2.5583333
A13: Site | B13: Pavona spp. | C13: Pocillopora effusa | D13: Porites lobata | E13: Psammocora stellata | F13: Substrate | G13: Sea grass | H13: Macroalgae | I13: CCA | J13: Filter feeders | K13: Diadema sp | L13: Soft Coral | O13: Site | P13: Pavona spp. | Q13: Pocillopora effusa | R13: Porites lobata | S13: Psammocora stellata | T13: Substrate | U13: Sea grass | V13: Macroalgae | W13: CCA | X13: Filter feeders | Y13: Diadema sp | Z13: Soft Coral | AC13: Site | AD13: Corals | AE13: Macroalgae | AF13: CCA | AG13: Sea grass | AH13: Substrate | AI13: Filter feeders | AJ13: Diadema sp
A14: Papagayo1 (10m) | B14: =SUM(B2:C2) -> 0 | C14: 10.755556 | D14: 0.13333333 | E14: 0 | F14: =SUM(L2:O2) -> 1.1111111 | G14: 0 | H14: =SUM(S2:U2,X2,P2) -> 37.866667 | I14: =SUM(Y2,V2:W2) -> 46.444444 | J14: =SUM(G2:H2,Q2,K2) -> 0.8 | K14: 2.6666667 | L14: 0.22222222 | O14: Papagayo (UW) | P14: =AVERAGE(B14:B19) -> 2.0740741 | Q14: =AVERAGE(C14:C19) -> 10.681481 | R14: =AVERAGE(D14:D19) -> 1.2296296 | S14: =AVERAGE(E14:E19) -> 0.12592593 | T14: =AVERAGE(F14:F19) -> 2.0962963 | U14: =AVERAGE(G14:G19) -> 0.88148148 | V14: =AVERAGE(H14:H19) -> 54.637037 | W14: =AVERAGE(I14:I19) -> 25.859259 | ... Z14: =AVERAGE(L14:L19) -> 0.081481481 | AC14: Papagayo (UW) | AD14: =SUM(P14:S14,Z14) -> 14.192593 | AE14: 54.637037 | AF14: 25.859259 | AG14: 0.88148148 | AH14: 2.0962963 | AI14: =SUM(X14) -> 0.25925926 | AJ14: 2.0740741
A15: Papagayo2 (10m) | B15: =SUM(B3:C3) -> 6.8 | C15: 4.9777778 | D15: 2.5777778 | E15: 0.4 | F15: =SUM(L3:O3) -> 5.3777778 | G15: 0.088888889 | H15: =SUM(S3:U3,X3,P3) -> 55.555556 | I15: =SUM(Y3,V3:W3) -> 22.533333 | J15: =SUM(G3:H3,Q3,K3) -> 0.13333333 | K15: 1.5111111 | L15: 0.044444444 | O15: Samara (NUW) | P15: =AVERAGE(B20:B23) -> 0.055555556 | Q15: =AVERAGE(C20:C23) -> 0.94444444 | R15: =AVERAGE(D20:D23) -> 6.0805556 | S15: =AVERAGE(E20:E23) -> 0.74444444 | T15: =AVERAGE(F20:F23) -> 3.7430556 | U15: =AVERAGE(G20:G23) -> 2.0111111 | V15: =AVERAGE(H20:H23) -> 75.441667 | W15: =AVERAGE(I20:I23) -> 9.3173611 | ... Z15: =AVERAGE(L20:L23) -> 1.3902778 | AC15: Samara (NUW) | AD15: =SUM(P15:S15,Z15) -> 9.2152778 | AE15: 75.441667 | AF15: 9.3173611 | AG15: 2.0111111 | AH15: 3.7430556 | AI15: =SUM(X15) -> 0.20486111 | AJ15: 0.066666667
A16: Papagayo3 (10m) | B16: =SUM(B4:C4) -> 1.8666667 | C16: 12.311111 | D16: 1.2444444 | E16: 0.17777778 | F16: =SUM(L4:O4) -> 2 | G16: 2.3555556 | H16: =SUM(S4:U4,X4,P4) -> 48.577778 | I16: =SUM(Y4,V4:W4) -> 27.466667 | J16: =SUM(G4:H4,Q4,K4) -> 0.22222222 | K16: 3.7777778 | L16: 0
A17: Papagayo4 (5m) | B17: =SUM(B5:C5) -> 0.31111111 | C17: 16.711111 | D17: 2.4888889 | E17: 0.17777778 | F17: =SUM(L5:O5) -> 0.84444444 | G17: 0.13333333 | H17: =SUM(S5:U5,X5,P5) -> 60.577778 | I17: =SUM(Y5,V5:W5) -> 15.822222 | J17: =SUM(G5:H5,Q5,K5) -> 0.044444444 | K17: 2.8888889 | L17: 0
A18: Papagayo5 (10m) | B18: =SUM(B6:C6) -> 2.6666667 | C18: 5.8222222 | D18: 0.44444444 | E18: 0 | F18: =SUM(L6:O6) -> 1.1555556 | G18: 0.044444444 | H18: =SUM(S6:U6,X6,P6) -> 64.177778 | I18: =SUM(Y6,V6:W6) -> 24.666667 | J18: =SUM(G6:H6,Q6,K6) -> 0.13333333 | K18: 0.75555556 | L18: 0.13333333
A19: Papagayo6 (5m) | B19: =SUM(B7:C7) -> 0.8 | C19: 13.511111 | D19: 0.48888889 | E19: 0 | F19: =SUM(L7:O7) -> 2.0888889 | G19: 2.6666667 | H19: =SUM(S7:U7,X7,P7) -> 61.066667 | I19: =SUM(Y7,V7:W7) -> 18.222222 | J19: =SUM(G7:H7,Q7,K7) -> 0.22222222 | K19: 0.84444444 | L19: 0.088888889
A20: Samara1 (5m) | B20: =SUM(B8:C8) -> 0 | C20: 0.66666667 | D20: 0.088888889 | E20: 0.66666667 | F20: =SUM(L8:O8) -> 2.7111111 | G20: 5.2888889 | H20: =SUM(S8:U8,X8,P8) -> 78.266667 | I20: =SUM(Y8,V8:W8) -> 12.177778 | J20: =SUM(G8:H8,Q8,K8) -> 0 | K20: 0.044444444 | L20: 0.088888889
A21: Samara2 (5m) | B21: =SUM(B9:C9) -> 0 | C21: 0.13333333 | D21: 20.4 | E21: 0 | F21: =SUM(L9:O9) -> 8.5777778 | G21: 0 | H21: =SUM(S9:U9,X9,P9) -> 64.755556 | I21: =SUM(Y9,V9:W9) -> 5.9111111 | J21: =SUM(G9:H9,Q9,K9) -> 0.044444444 | K21: 0.17777778 | L21: 0
A22: Samara3 (5m) | B22: =SUM(B10:C10) -> 0.22222222 | C22: 2.9777778 | D22: 2.2666667 | E22: 2.3111111 | F22: =SUM(L10:O10) -> 1.4666667 | G22: 2.7555556 | H22: =SUM(S10:U10,X10,P10) -> 82.577778 | I22: =SUM(Y10,V10:W10) -> 5.2888889 | J22: =SUM(G10:H10,Q10,K10) -> 0 | K22: 0.044444444 | L22: 0.088888889
A23: Samara4 (15m) | B23: =SUM(B11:C11) -> 0 | C23: 0 | D23: 1.5666667 | E23: 0 | F23: =SUM(L11:O11) -> 2.2166667 | G23: 0 | H23: =SUM(S11:U11,X11,P11) -> 76.166667 | I23: =SUM(Y11,V11:W11) -> 13.891667 | J23: =SUM(G11:H11,Q11,K11) -> 0.775 | K23: 0 | L23: 5.3833333
AF24: name | AG24: lat | AH24: lon | AI24: Deep
AF25: Samara-1 | AG25: 9.87222 | AH25: -85.531544 | AI25: 5
AF26: Samara-2 | AG26: 9.864684 | AH26: -85.51266 | AI26: 5
AF27: Samara-3 | AG27: 9.864811 | AH27: -85.496652 | AI27: 5
AF28: Samara-4 | AG28: 9.87222 | AH28: -85.531544 | AI28: 15
AF29: Papagayo-1 | AG29: 10.608739 | AH29: -85.703523 | AI29: 10
AF30: Papagayo-2 | AG30: 10.578611 | AH30: -85.712222 | AI30: 10
AF31: Papagayo-3 | AG31: 10.641943 | AH31: -85.696242 | AI31: 10
AF32: Papagayo-4 | AG32: 10.654966 | AH32: -85.672522 | AI32: 5
AF33: Papagayo-5 | AG33: 10.538276 | AH33: -85.785373 | AI33: 10
AF34: Papagayo-6 | AG34: 10.543297 | AH34: -85.774546 | AI34: 5

Sheet Normalety
A2: Site | B2: Pavona spp. | C2: Pocillopora effusa | D2: Porites lobata | E2: Psammocora stellata | F2: Substrate | G2: Sea grass | H2: Macroalgae | I2: CCA | J2: Filter feeders | K2: Diadema sp | L2: Soft Coral
A3: Papagayo1 (10m) | B3: 0 | C3: 10.755556 | D3: 0.13333333 | E3: 0 | F3: 1.1111111 | G3: 0 | H3: 37.866667 | I3: 46.444444 | J3: 0.8 | K3: 2.6666667 | L3: 0.22222222
A4: Papagayo2 (10m) | B4: 6.8 | C4: 4.9777778 | D4: 2.5777778 | E4: 0.4 | F4: 5.3777778 | G4: 0.088888889 | H4: 55.555556 | I4: 22.533333 | J4: 0.13333333 | K4: 1.5111111 | L4: 0.044444444
A5: Papagayo3 (10m) | B5: 1.8666667 | C5: 12.311111 | D5: 1.2444444 | E5: 0.17777778 | F5: 2 | G5: 2.3555556 | H5: 48.577778 | I5: 27.466667 | J5: 0.22222222 | K5: 3.7777778 | L5: 0
A6: Papagayo4 (5m) | B6: 0.31111111 | C6: 16.711111 | D6: 2.4888889 | E6: 0.17777778 | F6: 0.84444444 | G6: 0.13333333 | H6: 60.577778 | I6: 15.822222 | J6: 0.044444444 | K6: 2.8888889 | L6: 0
A7: Papagayo5 (10m) | B7: 2.6666667 | C7: 5.8222222 | D7: 0.44444444 | E7: 0 | F7: 1.1555556 | G7: 0.044444444 | H7: 64.177778 | I7: 24.666667 | J7: 0.13333333 | K7: 0.75555556 | L7: 0.13333333
A8: Papagayo6 (5m) | B8: 0.8 | C8: 13.511111 | D8: 0.48888889 | E8: 0 | F8: 2.0888889 | G8: 2.6666667 | H8: 61.066667 | I8: 18.222222 | J8: 0.22222222 | K8: 0.84444444 | L8: 0.088888889
A9: Samara1 (5m) | B9: 0 | C9: 0.66666667 | D9: 0.088888889 | E9: 0.66666667 | F9: 2.7111111 | G9: 5.2888889 | H9: 78.266667 | I9: 12.177778 | J9: 0 | K9: 0.044444444 | L9: 0.088888889
A10: Samara2 (5m) | B10: 0 | C10: 0.13333333 | D10: 20.4 | E10: 0 | F10: 8.5777778 | G10: 0 | H10: 64.755556 | I10: 5.9111111 | J10: 0.044444444 | K10: 0.17777778 | L10: 0
A11: Samara3 (5m) | B11: 0.22222222 | C11: 2.9777778 | D11: 2.2666667 | E11: 2.3111111 | F11: 1.4666667 | G11: 2.7555556 | H11: 82.577778 | I11: 5.2888889 | J11: 0 | K11: 0.044444444 | L11: 0.088888889
A12: Samara4 (15m) | B12: 0 | C12: 0 | D12: 1.5666667 | E12: 0 | F12: 2.2166667 | G12: 0 | H12: 76.166667 | I12: 13.891667 | J12: 0.775 | K12: 0 | L12: 5.3833333
A14: papagayo
A15: Test for normal distribution
A16: Shapiro-Wilk test
A17: W | B17: 0.8278 | C17: 0.9385 | D17: 0.8481 | E17: 0.8136 | F17: 0.7502 | G17: 0.6983 | H17: 0.895 | I17: 0.8447 | J17: 0.721 | K17: 0.9164 | L17: 0.9124
A18: P value | B18: 0.1029 | C18: 0.647 | D18: 0.152 | E18: 0.0775 | F18: 0.02 | G18: 0.0059 | H18: 0.3454 | I18: 0.1424 | J18: 0.0102 | K18: 0.4801 | L18: 0.4522
A19: Passed normality test (alpha=0.05)? | B19: Yes | C19: Yes | D19: Yes | E19: Yes | F19: No | G19: No | H19: Yes | I19: Yes | J19: No | K19: Yes | L19: Yes
A20: P value summary | B20: ns | C20: ns | D20: ns | E20: ns | F20: * | G20: ** | H20: ns | I20: ns | J20: * | K20: ns | L20: ns
A22: Kolmogorov-Smirnov test
A23: KS distance | B23: 0.2404 | C23: 0.191 | D23: 0.2548 | E23: 0.2843 | F23: 0.3351 | G23: 0.3892 | H23: 0.2265 | I23: 0.2749 | J23: 0.3873 | K23: 0.1859 | L23: 0.1724
A24: P value | B24: >0.1000 | C24: >0.1000 | D24: >0.1000 | E24: >0.1000 | F24: 0.0339 | G24: 0.0049 | H24: >0.1000 | I24: >0.1000 | J24: 0.0053 | K24: >0.1000 | L24: >0.1000
A25: Passed normality test (alpha=0.05)? | B25: Yes | C25: Yes | D25: Yes | E25: Yes | F25: No | G25: No | H25: Yes | I25: Yes | J25: No | K25: Yes | L25: Yes
A26: P value summary | B26: ns | C26: ns | D26: ns | E26: ns | F26: * | G26: ** | H26: ns | I26: ns | J26: ** | K26: ns | L26: ns
A28: Number of values | B28: 6 | C28: 6 | D28: 6 | E28: 6 | F28: 6 | G28: 6 | H28: 6 | I28: 6 | J28: 6 | K28: 6 | L28: 6
A30: samara
A31: Test for normal distribution
A32: Shapiro-Wilk test
A33: W | B33: 0.8278 | C33: 0.9385 | D33: 0.8481 | E33: 0.8136 | F33: 0.7502 | G33: 0.6983 | H33: 0.895 | I33: 0.8447 | J33: 0.721 | K33: 0.9164 | L33: 0.9124
A34: P value | B34: 0.1029 | C34: 0.647 | D34: 0.152 | E34: 0.0775 | F34: 0.02 | G34: 0.0059 | H34: 0.3454 | I34: 0.1424 | J34: 0.0102 | K34: 0.4801 | L34: 0.4522
A35: Passed normality test (alpha=0.05)? | B35: Yes | C35: Yes | D35: Yes | E35: Yes | F35: No | G35: No | H35: Yes | I35: Yes | J35: No | K35: Yes | L35: Yes
A36: P value summary | B36: ns | C36: ns | D36: ns | E36: ns | F36: * | G36: ** | H36: ns | I36: ns | J36: * | K36: ns | L36: ns
A38: Kolmogorov-Smirnov test
A39: KS distance | B39: 0.2404 | C39: 0.191 | D39: 0.2548 | E39: 0.2843 | F39: 0.3351 | G39: 0.3892 | H39: 0.2265 | I39: 0.2749 | J39: 0.3873 | K39: 0.1859 | L39: 0.1724
A40: P value | B40: >0.1000 | C40: >0.1000 | D40: >0.1000 | E40: >0.1000 | F40: 0.0339 | G40: 0.0049 | H40: >0.1000 | I40: >0.1000 | J40: 0.0053 | K40: >0.1000 | L40: >0.1000
A41: Passed normality test (alpha=0.05)? | B41: Yes | C41: Yes | D41: Yes | E41: Yes | F41: No | G41: No | H41: Yes | I41: Yes | J41: No | K41: Yes | L41: Yes
A42: P value summary | B42: ns | C42: ns | D42: ns | E42: ns | F42: * | G42: ** | H42: ns | I42: ns | J42: ** | K42: ns | L42: ns
A44: Number of values | B44: 6 | C44: 6 | D44: 6 | E44: 6 | F44: 6 | G44: 6 | H44: 6 | I44: 6 | J44: 6 | K44: 6 | L44: 6

Sheet homogeneity of variances
A1: papagayo species | H1: samara species
A3: Brown-Forsythe test | H3: Brown-Forsythe test
A4: F (DFn, DFd) | B4: 3.607 (10, 55) | H4: F (DFn, DFd) | I4: 1.267 (10, 33)
A5: P value | B5: 0.001 | H5: P value | I5: 0.2884
A6: P value summary | B6: *** | H6: P value summary | I6: ns
A7: Are SDs significantly different (P < 0.05)? | B7: Yes | H7: Are SDs significantly different (P < 0.05)? | I7: No
A9: Bartlett's test | H9: Bartlett's test
A10: Bartlett's statistic (corrected) | B10: 136.4 | H10: Bartlett's statistic (corrected) | I10: 65.86
A11: P value | B11: <0.0001 | H11: P value | I11: <0.0001
A12: P value summary | B12: **** | H12: P value summary | I12: ****
A13: Are SDs significantly different (P < 0.05)? | B13: Yes | H13: Are SDs significantly different (P < 0.05)? | I13: Yes
A20: Data summary | H20: Data summary
A21: Number of treatments (columns) | B21: 11 | H21: Number of treatments (columns) | I21: 11
A22: Number of values (total) | B22: 66 | H22: Number of values (total) | I22: 44
